<mujoco model="GR1T1_inspire_hand_simple_coll">
  <compiler angle="radian" meshdir="../meshes" eulerseq="zyx" autolimits="true"/> 
  <option timestep='0.002' iterations='50' solver='PGS' gravity='0 0 -9.81'>
  <flag sensornoise="enable" frictionloss="enable"/>
  </option>
  <size njmax="500" nconmax="100" />

  <visual>
      <quality shadowsize='4096'/>
      <map znear='0.05'/>
  </visual>

  <default>
      <default class="GR1T1_inspire_hand_simple_coll">
          <joint limited='true'/>
      <motor ctrllimited='true'/>
      <geom  condim='4' contype="1" conaffinity="15" solref='0.001 2' friction='0.9 0.2 0.2'/>
      <equality solref='0.001 2'/>
      <default class='visualgeom'>
          <geom material='visualgeom' condim='1' contype='0' conaffinity='0'/>
      </default>
      <default class='visualgeom2'>
          <geom material='visualgeom2' condim='1' contype='0' conaffinity='0'/>
      </default>
      <default class='obstacle'>
          <geom material='obstacle' condim='3' contype='1' conaffinity='15'/>
      </default>


      <default class='neck_joint_param'>
          <joint  damping="0.01" frictionloss="0.01" armature="0.01"/>
      </default>

      <default class='waist_joint_param'>
          <joint  damping="2" frictionloss="2" armature="0.01"/>
      </default>

      <default class='leg_joint_param'>
          <joint  damping="0.01" frictionloss="0.01" armature="0.01"/>
      </default>

      <default class='arm_joint_param'>
          <joint  damping="1" frictionloss="1" armature="0.01"/>
      </default>

      <default class='finger_joint_param'>
          <joint  damping="0.00" frictionloss="0.00" armature="0.01"/>
      </default>
          <default class="visual">
              <geom type="mesh" contype="0" conaffinity="0" group="2"/>
          </default>
          <default class="collision">
              <geom group="3" mass="0" density="0"/>
              <default class="base_collision">
                  <geom type="capsule" size=".014"/>
              </default>
          </default>
          <site size="0.001" rgba="0.5 0.5 0.5 0.3" group="4"/>
      </default>
    </default>
  	


  <asset>
    <texture type="skybox" builtin="gradient" rgb1="0.3 0.5 0.7" rgb2="0 0 0" width="512" height="512"/>
    	<texture name="texplane" type="2d" builtin="checker" rgb1=".2 .3 .4" rgb2=".1 0.15 0.2"
        width="512" height="512" mark="cross" markrgb=".8 .8 .8"/>
    	<texture name="texplane2" type="2d" builtin="checker" rgb1="1 0.3137 0.1843" rgb2="0.0 0.30196 0.38039"
        width="512" height="512" mark="cross" markrgb=".8 .8 .8"/>

   	<material name="matplane" reflectance="0." texture="texplane" texrepeat="1 1" texuniform="true"/>
   	<material name="matplane2" reflectance="0.1" texture="texplane2" texrepeat="1 1" texuniform="true"/>

  	<material name='obstacle'  rgba='0.9 0.6 0.2 1'/>
  	<material name='visualgeom'  rgba='0.5 0.9 0.2 1'/>
  	<material name='visualgeom2'  rgba='0.5 0.9 0.2 1'/>
        <mesh name="base_link" file="base_link.STL"/>
        <mesh name="left_thigh_roll_link" file="left_thigh_roll_link.STL"/>
        <mesh name="left_thigh_yaw_link" file="left_thigh_yaw_link.STL"/>
        <mesh name="left_thigh_pitch_link" file="left_thigh_pitch_link.STL"/>
        <mesh name="left_shank_pitch_link" file="left_shank_pitch_link.STL"/>
        <mesh name="left_foot_pitch_link" file="left_foot_pitch_link.STL"/>
        <mesh name="left_foot_roll_link" file="left_foot_roll_link.STL"/>
        <mesh name="right_thigh_roll_link" file="right_thigh_roll_link.STL"/>
        <mesh name="right_thigh_yaw_link" file="right_thigh_yaw_link.STL"/>
        <mesh name="right_thigh_pitch_link" file="right_thigh_pitch_link.STL"/>
        <mesh name="right_shank_pitch_link" file="right_shank_pitch_link.STL"/>
        <mesh name="right_foot_pitch_link" file="right_foot_pitch_link.STL"/>
        <mesh name="right_foot_roll_link" file="right_foot_roll_link.STL"/>
        <mesh name="waist_yaw_link" file="waist_yaw_link.STL"/>
        <mesh name="waist_pitch_link" file="waist_pitch_link.STL"/>
        <mesh name="waist_roll_link" file="waist_roll_link.STL"/>
        <mesh name="head_yaw_link" file="head_yaw_link.STL"/>
        <mesh name="head_roll_link" file="head_roll_link.STL"/>
        <mesh name="head_pitch_link" file="head_pitch_link.STL"/>
        <mesh name="left_upper_arm_pitch_link" file="left_upper_arm_pitch_link.STL"/>
        <mesh name="left_upper_arm_roll_link" file="left_upper_arm_roll_link.STL"/>
        <mesh name="left_upper_arm_yaw_link" file="left_upper_arm_yaw_link.STL"/>
        <mesh name="left_lower_arm_pitch_link" file="left_lower_arm_pitch_link.STL"/>
        <mesh name="left_hand_yaw_link" file="left_hand_yaw_link.STL"/>
        <mesh name="left_hand_roll_link" file="left_hand_roll_link.STL"/>
        <mesh name="left_hand_pitch_link" file="left_hand_pitch_link.STL"/>
        <mesh name="right_upper_arm_pitch_link" file="right_upper_arm_pitch_link.STL"/>
        <mesh name="right_upper_arm_roll_link" file="right_upper_arm_roll_link.STL"/>
        <mesh name="right_upper_arm_yaw_link" file="right_upper_arm_yaw_link.STL"/>
        <mesh name="right_lower_arm_pitch_link" file="right_lower_arm_pitch_link.STL"/>
        <mesh name="right_hand_yaw_link" file="right_hand_yaw_link.STL"/>
        <mesh name="right_hand_roll_link" file="right_hand_roll_link.STL"/>
        <mesh name="right_hand_pitch_link" file="right_hand_pitch_link.STL"/>
        <mesh name="IMU_link" file="IMU_link.STL"/>
        <mesh name="torso_link" file="torso_link.STL"/>
        <mesh name="L_hand_base_link" file="fourier_hand/l_hand_base_link.STL"/>
        <mesh name="L_index_intermediate" file="inspire_hand/Link16_l.STL"/>
        <mesh name="L_index_proximal" file="inspire_hand/Link15_l.STL"/>
        <mesh name="L_middle_intermediate" file="inspire_hand/Link18_l.STL"/>
        <mesh name="L_middle_proximal" file="inspire_hand/Link17_l.STL"/>
        <mesh name="L_pinky_intermediate" file="inspire_hand/Link22_l.STL"/>
        <mesh name="L_pinky_proximal" file="inspire_hand/Link21_l.STL"/>
        <mesh name="L_ring_intermediate" file="inspire_hand/Link20_l.STL"/>
        <mesh name="L_ring_proximal" file="inspire_hand/Link19_l.STL"/>
        <mesh name="L_thumb_distal" file="inspire_hand/Link14_l.STL"/>
        <mesh name="L_thumb_intermediate" file="inspire_hand/Link13_l.STL"/>
        <mesh name="L_thumb_proximal" file="inspire_hand/Link12_l.STL"/>
        <mesh name="L_thumb_proximal_base" file="inspire_hand/Link11_l.STL"/>
        <mesh name="R_hand_base_link" file="fourier_hand/r_hand_base_link.STL"/>
<!--        <mesh name="R_hand_base_link" file="inspire_hand/base_link_r.STL"/>-->
        <mesh name="R_index_intermediate" file="inspire_hand/Link16_r.STL"/>
        <mesh name="R_index_proximal" file="inspire_hand/Link15_r.STL"/>
        <mesh name="R_middle_intermediate" file="inspire_hand/Link18_r.STL"/>
        <mesh name="R_middle_proximal" file="inspire_hand/Link17_r.STL"/>
        <mesh name="R_pinky_intermediate" file="inspire_hand/Link22_r.STL"/>
        <mesh name="R_pinky_proximal" file="inspire_hand/Link21_r.STL"/>
        <mesh name="R_ring_intermediate" file="inspire_hand/Link20_r.STL"/>
        <mesh name="R_ring_proximal" file="inspire_hand/Link19_r.STL"/>
        <mesh name="R_thumb_distal" file="inspire_hand/Link14_r.STL"/>
        <mesh name="R_thumb_intermediate" file="inspire_hand/Link13_r.STL"/>
        <mesh name="R_thumb_proximal" file="inspire_hand/Link12_r.STL"/>
        <mesh name="R_thumb_proximal_base" file="inspire_hand/Link11_r.STL"/>


  </asset>

  <worldbody>
        <light mode="targetbodycom" target="base_link" pos="2 0 2.5"/>
	<geom name="ground" type="plane" size="0 0 1" pos="0.001 0 0" quat="1 0 0 0" material="matplane" condim="1" conaffinity='15'/>
	
    <body name="base_link" pos="0 0 0.87">
      <inertial pos="-0.06584 -9.765e-05 -0.01434" quat="0.384085 0.384189 -0.593878 0.593453" mass="3.84" diaginertia="0.0357335 0.0311265 0.01048" />
      <site name='imu' size='0.01' pos='-0.0648 0 -0.1015'/>
      <freejoint/>
<!--      <geom class="visual" rgba="0.752941 0.752941 0.752941 1" mesh="base_link"/>-->
      <geom type="mesh" contype="0" conaffinity="0" group="1" density="0" rgba="0.75294 0.75294 0.75294 1" mesh="base_link" />
      <geom type="mesh" rgba="0.75294 0.75294 0.75294 1" mesh="base_link" class="visualgeom"/>
<!--      <geom name="base_link.STL" size="0.122394 0.0685504" pos="-0.0425829 0.000370042 0.00921009" quat="0.706838 -0.707359 0.00477667 0" type="cylinder" rgba="0.752941 0.752941 0.752941 1" />-->
      <body name="left_thigh_roll_link" pos="-0.0025 0.105 -0.0276">
        <inertial pos="0.04163 3.4568e-05 -0.0021382" quat="0.575529 0.581908 -0.40597 0.406619" mass="1.1437" diaginertia="0.00117548 0.00100413 0.000943892" />
        <joint name="left_hip_roll_joint" pos="0 0 0" axis="1 0 0" range="-0.09 0.39" class="leg_joint_param"/>
        <geom type="mesh" contype="0" conaffinity="0" group="1" density="0" rgba="0.75294 0.75294 0.75294 1" mesh="left_thigh_roll_link" />
        <geom type="mesh" rgba="0.75294 0.75294 0.75294 1" mesh="left_thigh_roll_link" class="visualgeom"/>
        <body name="left_thigh_yaw_link">
          <inertial pos="0.00018348 0.046462 -0.10389" quat="0.704251 -0.0226446 -0.0453749 0.708138" mass="3.9888" diaginertia="0.0163385 0.0100158 0.00924336" />
          <joint name="left_hip_yaw_joint" pos="0 0 0" axis="0 0 1" range="-0.7 0.7" class="leg_joint_param"/>
          <geom type="mesh" contype="0" conaffinity="0" group="1" density="0" rgba="0.75294 0.75294 0.75294 1" mesh="left_thigh_yaw_link" />
	  <geom type="mesh" rgba="0.75294 0.75294 0.75294 1" mesh="left_thigh_yaw_link" class="visualgeom"/>
          <body name="left_thigh_pitch_link" pos="0 0.0223 -0.1405">
            <inertial pos="0.0028493 -0.021688 -0.090886" quat="0.707411 -0.0125435 -0.0111264 0.706604" mass="6.569" diaginertia="0.0532352 0.0425096 0.0134363" />
            <joint name="left_hip_pitch_joint" pos="0 0 0" axis="0 1 0" range="-1.75 0.7" class="leg_joint_param"/>
            <geom type="mesh" contype="0" conaffinity="0" group="1" density="0" rgba="0.75294 0.75294 0.75294 1" mesh="left_thigh_pitch_link" />
	    <geom type="mesh" rgba="0.75294 0.75294 0.75294 1" mesh="left_thigh_pitch_link" class="visualgeom"/>
            <body name="left_shank_pitch_link" pos="0 -0.0213 -0.36">
              <inertial pos="0.0024312 -2.9945e-05 -0.11554" quat="0.692137 0.00134576 0.00140217 0.721764" mass="2.3895" diaginertia="0.0162703 0.016117 0.00113627" />
              <joint name="left_knee_pitch_joint" pos="0 0 0" axis="0 1 0" range="-0.09 1.92" class="leg_joint_param"/>
              <geom type="mesh" contype="0" conaffinity="0" group="1" density="0" rgba="0.75294 0.75294 0.75294 1" mesh="left_shank_pitch_link" />
	          <geom type="mesh" rgba="0.75294 0.75294 0.75294 1" mesh="left_shank_pitch_link" class="visualgeom"/>
              <body name="left_foot_pitch_link" pos="0 0 -0.34">
                <inertial pos="1.748e-11 4.3804e-11 0" quat="1 3.42295e-05 -6.07362e-06 -2.07897e-10" mass="0.080335" diaginertia="5.1022e-06 4.3976e-06 4.188e-06" />
<!--                <geom type="mesh" contype="0" conaffinity="0" group="1" density="0" rgba="0.75294 0.75294 0.75294 1" mesh="left_foot_pitch_link" />-->
<!--	            <geom type="mesh" rgba="0.75294 0.75294 0.75294 1" mesh="left_foot_pitch_link" class="visualgeom"/>-->
                <joint name="left_ankle_pitch_joint" pos="0 0 0" axis="0 1 0" range="-1.05 0.52" class="leg_joint_param" frictionloss="0.05"/>
                <geom type="mesh" contype="0" conaffinity="0" group="1" density="0" rgba="0.75294 0.75294 0.75294 1" mesh="left_foot_pitch_link"/>
                <geom type="mesh" rgba="0.752941 0.752941 0.752941 1" mesh="left_foot_pitch_link" class="visualgeom"/>
                <geom type="mesh" contype="0" conaffinity="0" group="1" density="0" rgba="0.75294 0.75294 0.75294 1" mesh="left_foot_pitch_link" />
                <geom type="mesh" rgba="0.75294 0.75294 0.75294 1" mesh="left_foot_pitch_link" class="visualgeom"/>
                <body name="left_foot_roll_link">
                  <inertial pos="0.039446 0.00035757 -0.038101" quat="-0.00087198 0.709539 -0.00177594 0.704664" mass="0.584" diaginertia="0.00271032 0.0024027 0.000369145" />
                  <joint name="left_ankle_roll_joint" pos="0 0 0" axis="1 0 0" range="-0.44 0.44" />
                  <geom class="visual" rgba="0.75294 0.75294 0.75294 1" mesh="left_foot_roll_link" />
                  <geom class="collision" name="l_foot" size="0.015 0.06 0.15" pos="0.05 0 -0.035" quat="0.707105 0 0.707108 0" type="box" rgba="0.75294 0.75294 0.75294 1"/>

                </body>
              </body>
            </body>
          </body>
        </body>
      </body>
      <body name="right_thigh_roll_link" pos="-0.0025 -0.105 -0.0276">
        <inertial pos="0.0416295 3.45678e-05 -0.00213824" quat="0.57555 0.581927 -0.405942 0.406589" mass="1.14367" diaginertia="0.00117548 0.00100417 0.000943891" />
        <joint name="right_hip_roll_joint" pos="0 0 0" axis="1 0 0" range="-0.39 0.09"  class="leg_joint_param"/>
        <geom type="mesh" contype="0" conaffinity="0" group="1" density="0" rgba="0.75294 0.75294 0.75294 1" mesh="right_thigh_roll_link" />
        <geom type="mesh" rgba="0.75294 0.75294 0.75294 1" mesh="right_thigh_roll_link" class="visualgeom"/>
        <body name="right_thigh_yaw_link">
          <inertial pos="-0.00159762 -0.0464482 -0.103899" quat="0.709186 -0.0420808 -0.0194028 0.703497" mass="3.98882" diaginertia="0.0163388 0.0100142 0.00924469" />
          <joint name="right_hip_yaw_joint" pos="0 0 0" axis="0 0 1" range="-0.7 0.7" class="leg_joint_param"/>
          <geom type="mesh" contype="0" conaffinity="0" group="1" density="0" rgba="0.75294 0.75294 0.75294 1" mesh="right_thigh_yaw_link" />
          <geom type="mesh" rgba="0.75294 0.75294 0.75294 1" mesh="right_thigh_yaw_link" class="visualgeom"/>
          <body name="right_thigh_pitch_link" pos="0 -0.0223 -0.1405">
            <inertial pos="0.002842 0.0217009 -0.0919987" quat="0.706586 -0.0113774 -0.0126258 0.707423" mass="6.56895" diaginertia="0.0532349 0.0424818 0.0134641" />
            <joint name="right_hip_pitch_joint" pos="0 0 0" axis="0 1 0" range="-1.75 0.7" class="leg_joint_param"/>
            <geom type="mesh" contype="0" conaffinity="0" group="1" density="0" rgba="0.75294 0.75294 0.75294 1" mesh="right_thigh_pitch_link" />
            <geom type="mesh" rgba="0.75294 0.75294 0.75294 1" mesh="right_thigh_pitch_link" class="visualgeom"/>
<!--            <geom name="right_thigh_pitch_link.STL" size="0.085878 0.124911" pos="-0.00212327 0.0301596 -0.167056" quat="0.999971 0.00269833 0.00706272 0" type="cylinder" rgba="0.752941 0.752941 0.752941 1" />-->
            <body name="right_shank_pitch_link" pos="0 0.0213 -0.36">
              <inertial pos="0.00236658 4.56188e-05 -0.115532" quat="0.71872 0.00154106 0.00120241 0.695296" mass="2.38947" diaginertia="0.0162708 0.0161183 0.00113536" />
              <joint name="right_knee_pitch_joint" pos="0 0 0" axis="0 1 0" range="-0.09 1.92" class="leg_joint_param"/>
              <geom type="mesh" contype="0" conaffinity="0" group="1" density="0" rgba="0.75294 0.75294 0.75294 1" mesh="right_shank_pitch_link" />
              <geom type="mesh" rgba="0.75294 0.75294 0.75294 1" mesh="right_shank_pitch_link" class="visualgeom"/>
<!--              <geom name="right_shank_pitch_link.STL" size="0.0533211 0.0903841" pos="-1.65901e-05 -0.000842557 -0.174699" type="cylinder" rgba="0.752941 0.752941 0.752941 1" />-->
              <body name="right_foot_pitch_link" pos="0 0 -0.34">
                <inertial pos="1.75705e-11 4.40342e-11 0" quat="1 3.42336e-05 -6.07409e-06 -2.07938e-10" mass="0.0799219" diaginertia="5.11122e-06 4.40004e-06 4.17954e-06" />
                <joint name="right_ankle_pitch_joint" pos="0 0 0" axis="0 1 0" range="-1.05 0.52" class="leg_joint_param" frictionloss="0.05"/>
<!--                <geom type="mesh" contype="0" conaffinity="0" group="1" density="0" rgba="0.75294 0.75294 0.75294 1" mesh="right_foot_pitch_link" />-->
<!--                <geom type="mesh" rgba="0.75294 0.75294 0.75294 1" mesh="right_foot_pitch_link" class="visualgeom"/>-->
                <geom type="mesh" contype="0" conaffinity="0" group="1" density="0" rgba="0.75294 0.75294 0.75294 1" mesh="right_foot_pitch_link" />
                <geom type="mesh" rgba="0.75294 0.75294 0.75294 1" mesh="right_foot_pitch_link" class="visualgeom"/>
                <body name="right_foot_roll_link">
                  <inertial pos="0.043909 -0.00032475 -0.039419" quat="0.000727105 0.710094 0.00155959 0.704104" mass="0.58089" diaginertia="0.00280098 0.0024886 0.000368482" />
                  <joint name="right_ankle_roll_joint" pos="0 0 0" axis="1 0 0" range="-0.44 0.44" />
                  <geom class="visual" rgba="0.75294 0.75294 0.75294 1" mesh="right_foot_roll_link" />
                  <geom class="collision" name="r_foot" size="0.015 0.06 0.15" pos="0.05 0 -0.035" quat="0.707105 0 0.707108 0" type="box" rgba="0.75294 0.75294 0.75294 1"/>

                </body>
              </body>
            </body>
          </body>
        </body>
      </body>
      <body name="waist_yaw_link">
        <inertial pos="-0.002641 -0.009332 0.05066" quat="0.967239 0.191378 -0.0307135 0.163948" mass="1.49" diaginertia="0.00303371 0.00290717 0.00146913" />
        <geom type="mesh" contype="0" conaffinity="0" group="1" density="0" rgba="0.75294 0.75294 0.75294 1" mesh="waist_yaw_link" />
        <geom type="mesh" rgba="0.75294 0.75294 0.75294 1" mesh="waist_yaw_link" class="visualgeom"/>
        <body name="waist_pitch_link" pos="0 0 0.0873">
          <inertial pos="0.00451 -0.00439 0.0406" quat="0.531996 0.0125456 0.0669515 0.844003" mass="1.62" diaginertia="0.0045927 0.00458165 0.00180365" />
          <geom type="mesh" contype="0" conaffinity="0" group="1" density="0" rgba="0.75294 0.75294 0.75294 1" mesh="waist_pitch_link" />
          <geom type="mesh" rgba="0.75294 0.75294 0.75294 1" mesh="waist_pitch_link" class="visualgeom"/>
          <body name="waist_roll_link" pos="0 0 0.081">
            <inertial pos="0.01038 -1.48e-06 0.01312" quat="0.31535 0.63338 0.631998 0.31617" mass="0.91" diaginertia="0.001226 0.00120045 0.000886551" />
            <geom type="mesh" contype="0" conaffinity="0" group="1" density="0" rgba="0.75294 0.75294 0.75294 1" mesh="waist_roll_link" />
            <geom type="mesh" rgba="0.75294 0.75294 0.75294 1" mesh="waist_roll_link" class="visualgeom"/>
            <body name="torso_link" pos="-0.00414 0 0.16071">
              <inertial pos="-0.00667 0.0001533 0.01837" quat="0.998658 0.00114289 0.0517712 0.000838218" mass="6.4" diaginertia="0.0417958 0.03127 0.0253542" />
              <geom type="mesh" contype="0" conaffinity="0" group="1" density="0" rgba="0.75294 0.75294 0.75294 1" mesh="torso_link" />
              <geom type="mesh" rgba="0.75294 0.75294 0.75294 1" mesh="torso_link" class="visualgeom"/>
<!--              <geom name="torso_link.STL" size="0.127427 0.080193" pos="-0.0158159 0.00519537 -0.0125205" type="cylinder" rgba="0.752941 0.752941 0.752941 1" />-->
              <body name="left_upper_arm_pitch_link" pos="0 0.10111 0.047149" quat="0.976296 0.216438 0 0">
                <geom type="mesh" contype="0" conaffinity="0" group="1" density="0" rgba="0.75294 0.75294 0.75294 1" mesh="left_upper_arm_pitch_link" />
                <geom type="mesh" rgba="0.75294 0.75294 0.75294 1" mesh="left_upper_arm_pitch_link" class="visualgeom"/>
                 <inertial pos="0.00515733 0.0588337 0.000122944" quat="0.999793 0.0203364 -0.000117253 0.0011083" mass="0.777394" diaginertia="0.000546411 0.000340581 0.000319359" />
                <body name="left_upper_arm_roll_link" pos="0 0.09515 0" quat="0.997189 -0.0749297 0 0">
                  <geom type="mesh" contype="0" conaffinity="0" group="1" density="0" rgba="0.75294 0.75294 0.75294 1" mesh="left_upper_arm_roll_link" />
                  <geom type="mesh" rgba="0.75294 0.75294 0.75294 1" mesh="left_upper_arm_roll_link" class="visualgeom"/>
                  <inertial pos="0.026005 0.02383 -0.027208" quat="0.906709 0.298574 0.22873 -0.190826" mass="0.084111" diaginertia="9.66715e-05 8.99185e-05 2.5473e-05" />
                  <body name="left_upper_arm_yaw_link" pos="0 0.04 -0.07095">
                    <inertial pos="5.47e-05 0.002013 -0.0852" quat="0.999468 0.0150745 0.000700882 -0.0289205" mass="0.55" diaginertia="0.00354401 0.00353998 0.000248202" />
                    <geom type="mesh" contype="0" conaffinity="0" group="1" density="0" rgba="0.75294 0.75294 0.75294 1" mesh="left_upper_arm_yaw_link" />
                    <geom type="mesh" rgba="0.75294 0.75294 0.75294 1" mesh="left_upper_arm_yaw_link" class="visualgeom"/>
<!--                    <geom name="left_upper_arm_yaw_link.STL" size="0.0362332 0.084942" pos="3.94854e-05 -0.00089429 -0.07934" quat="0.00803418 -0.995528 0.0941277 0" type="cylinder" rgba="0.752941 0.752941 0.752941 1" />-->
                    <body name="left_lower_arm_pitch_link" pos="0 0 -0.1751" quat="0.988771 0 -0.149438 0">>
                      <inertial pos="2.6052e-07 0.019694 -0.02109" quat="0.675255 -0.209847 0.209838 0.675251" mass="0.055396" diaginertia="2.92256e-05 2.63267e-05 1.3293e-05" />
                      <geom type="mesh" contype="0" conaffinity="0" group="1" density="0" rgba="0.75294 0.75294 0.75294 1" mesh="left_lower_arm_pitch_link" />
                      <geom type="mesh" rgba="0.75294 0.75294 0.75294 1" mesh="left_lower_arm_pitch_link" class="visualgeom"/>
                      <body name="left_hand_yaw_link" pos="0 5.033e-05 -0.05395">
                        <inertial pos="-2.923e-05 0.002124 -0.06117" quat="0.998548 0.00515378 -0.00372064 0.0534915" mass="0.73" diaginertia="0.00186712 0.00186313 0.00032085" />
                        <geom type="mesh" contype="0" conaffinity="0" group="1" density="0" rgba="0.75294 0.75294 0.75294 1" mesh="left_hand_yaw_link" />
                        <geom type="mesh" rgba="0.75294 0.75294 0.75294 1" mesh="left_hand_yaw_link" class="visualgeom"/>
<!--                        <geom name="left_hand_yaw_link.STL" size="0.0415719 0.0695937" pos="0.00108925 -0.00154111 -0.0760429" type="cylinder" rgba="0.752941 0.752941 0.752941 1" />-->
                        <body name="left_hand_roll_link" pos="0 0 -0.18765">
                          <inertial pos="0 0.001292 -0.01174" quat="0.579981 0.404502 0.579981 0.404502" mass="0.02955" diaginertia="1.01694e-05 8.75063e-06 5.38e-06" />
                          <geom type="mesh" contype="0" conaffinity="0" group="1" density="0" rgba="0.75294 0.75294 0.75294 1" mesh="left_hand_roll_link" />
                          <geom type="mesh" rgba="0.75294 0.75294 0.75294 1" mesh="left_hand_roll_link" class="visualgeom"/>
                          <body name="left_hand_pitch_link" >
                            <inertial pos="0 0.001292 -0.01174" quat="0.579981 0.404502 0.579981 0.404502" mass="0.02955" diaginertia="1.01694e-05 8.75063e-06 5.38e-06" />
                            <geom type="mesh" contype="0" conaffinity="0" group="1" density="0" rgba="0.75294 0.75294 0.75294 1" mesh="left_hand_pitch_link" />
                            <geom type="mesh" rgba="0.75294 0.75294 0.75294 1" mesh="left_hand_pitch_link" class="visualgeom"/>
                            <body name="left_end_effector_link" >
                              <body name="L_hand_base_link" pos="0 0 -0.022" >
                                <inertial pos="-0.002551 -0.066047 -0.0019357" quat="0.992433 0.118422 0.021189 0.0245586" mass="0.14143" diaginertia="0.000123583 8.41243e-05 7.6759e-05" />
                                <geom type="mesh" contype="0" conaffinity="0" group="1" density="0" rgba="0.75294 0.75294 0.75294 1" mesh="L_hand_base_link" />
                                <geom type="mesh" rgba="0.75294 0.75294 0.75294 1" mesh="L_hand_base_link" class="visualgeom"/>
                                <body name="L_thumb_proximal_base" pos="0.02045 -0.01696 -0.0691" quat="0.000796327 1 0 0">
                                  <inertial pos="-0.0048817 0.00038782 -0.00722" quat="0.445981 0.352284 0.495833 0.656617" mass="0.0018869" diaginertia="8.66031e-08 6.87331e-08 4.94199e-08" />
                                  <geom type="mesh" contype="0" conaffinity="0" group="1" density="0" rgba="0.75294 0.75294 0.75294 1" mesh="L_thumb_proximal_base" />
                                  <geom type="mesh" rgba="0.75294 0.75294 0.75294 1" mesh="L_thumb_proximal_base" class="visualgeom"/>
                                  <body name="L_thumb_proximal" pos="0.0099867 0.0098242 -0.0089" quat="0.704571 -0.704573 -0.0598169 0.0598167">
                                    <inertial pos="0.021936 -0.01279 -0.0080386" quat="0.25452 0.660687 -0.251949 0.659723" mass="0.0066101" diaginertia="2.78701e-06 2.44024e-06 8.6466e-07" />
                                    <geom type="mesh" contype="0" conaffinity="0" group="1" density="0" rgba="0.75294 0.75294 0.75294 1" mesh="L_thumb_proximal" />
                                    <geom type="mesh" rgba="0.75294 0.75294 0.75294 1" mesh="L_thumb_proximal" class="visualgeom"/>
                                    <body name="L_thumb_intermediate" pos="0.04407 -0.034553 -0.0008">
                                      <inertial pos="0.0095531 0.0016282 -0.0072002" quat="0.30738 0.636732 -0.307526 0.636803" mass="0.0037844" diaginertia="4.6532e-07 4.48114e-07 2.45646e-07" />
                                      <geom type="mesh" contype="0" conaffinity="0" group="1" density="0" rgba="0.75294 0.75294 0.75294 1" mesh="L_thumb_intermediate" />
                                      <geom type="mesh" rgba="0.75294 0.75294 0.75294 1" mesh="L_thumb_intermediate" class="visualgeom"/>
                                      <body name="L_thumb_distal" pos="0.020248 -0.010156 -0.0012">
                                        <inertial pos="0.0092888 -0.004953 -0.0060033" quat="0.266264 0.65596 -0.262836 0.655544" mass="0.003344" diaginertia="2.0026e-07 1.95246e-07 8.1594e-08" />
                                        <geom type="mesh" contype="0" conaffinity="0" group="1" density="0" rgba="0.75294 0.75294 0.75294 1" mesh="L_thumb_distal" />
                                        <geom type="mesh" rgba="0.75294 0.75294 0.75294 1" mesh="L_thumb_distal" class="visualgeom"/>
                                        <body name="L_thumb_tip" pos="0.015 -0.013 -0.004" />
                                      </body>
                                    </body>
                                  </body>
                                </body>
                                <body name="L_index_proximal" pos="0.032268 0.00028533 -0.13653" quat="0.491196 0.50865 0.491199 0.50865">
                                  <inertial pos="0.0012971 -0.011934 -0.0059998" quat="0.489677 0.510115 -0.489692 0.510099" mass="0.0042405" diaginertia="6.9402e-07 6.62904e-07 2.10916e-07" />
                                  <geom type="mesh" contype="0" conaffinity="0" group="1" density="0" rgba="0.75294 0.75294 0.75294 1" mesh="L_index_proximal" />
                                  <geom type="mesh" rgba="0.75294 0.75294 0.75294 1" mesh="L_index_proximal" class="visualgeom"/>
                                  <body name="L_index_intermediate" pos="-0.0024229 -0.032041 -0.001">
                                    <inertial pos="0.0021753 -0.019567 -0.005" quat="0.528694 0.469555 -0.528694 0.469555" mass="0.0045682" diaginertia="7.8176e-07 7.72427e-07 8.47209e-08" />
                                    <geom type="mesh" contype="0" conaffinity="0" group="1" density="0" rgba="0.75294 0.75294 0.75294 1" mesh="L_index_intermediate" />
                                    <geom type="mesh" rgba="0.75294 0.75294 0.75294 1" mesh="L_index_intermediate" class="visualgeom"/>
                                    <body name="L_index_tip" pos="-0.005 -0.04 -0.004" />
                                  </body>
                                </body>
                                <body name="L_middle_proximal" pos="0.01295 0.00028533 -0.1371" quat="0.499998 0.5 0.500002 0.5">
                                  <inertial pos="0.0012971 -0.011934 -0.0059999" quat="0.489677 0.510115 -0.489692 0.510099" mass="0.0042405" diaginertia="6.9402e-07 6.62904e-07 2.10916e-07" />
                                  <geom type="mesh" contype="0" conaffinity="0" group="1" density="0" rgba="0.75294 0.75294 0.75294 1" mesh="L_middle_proximal" />
                                  <geom type="mesh" rgba="0.75294 0.75294 0.75294 1" mesh="L_middle_proximal" class="visualgeom"/>
                                  <body name="L_middle_intermediate" pos="-0.0024229 -0.032041 -0.001">
                                    <inertial pos="0.001921 -0.020796 -0.0049999" quat="0.531603 0.466115 -0.531728 0.466262" mass="0.0050397" diaginertia="9.8385e-07 9.73288e-07 9.14016e-08" />
                                    <geom type="mesh" contype="0" conaffinity="0" group="1" density="0" rgba="0.75294 0.75294 0.75294 1" mesh="L_middle_intermediate" />
                                    <geom type="mesh" rgba="0.75294 0.75294 0.75294 1" mesh="L_middle_intermediate" class="visualgeom"/>
                                    <body name="L_middle_tip" pos="-0.005 -0.045 -0.004" />
                                  </body>
                                </body>
                                <body name="L_ring_proximal" pos="-0.0062872 0.00028533 -0.13691" quat="0.512915 0.48674 0.512919 0.48674">
                                  <inertial pos="0.0012971 -0.011934 -0.0059999" quat="0.489677 0.510114 -0.489692 0.510099" mass="0.0042405" diaginertia="6.9402e-07 6.62904e-07 2.10916e-07" />
                                  <geom type="mesh" contype="0" conaffinity="0" group="1" density="0" rgba="0.75294 0.75294 0.75294 1" mesh="L_ring_proximal" />
                                  <geom type="mesh" rgba="0.75294 0.75294 0.75294 1" mesh="L_ring_proximal" class="visualgeom"/>
                                  <body name="L_ring_intermediate" pos="-0.0024229 -0.032041 -0.001">
                                    <inertial pos="0.0021753 -0.019567 -0.005" quat="0.528694 0.469556 -0.528694 0.469556" mass="0.0045682" diaginertia="7.8176e-07 7.72437e-07 8.47208e-08" />
                                    <geom type="mesh" contype="0" conaffinity="0" group="1" density="0" rgba="0.75294 0.75294 0.75294 1" mesh="L_ring_intermediate" />
                                    <geom type="mesh" rgba="0.75294 0.75294 0.75294 1" mesh="L_ring_intermediate" class="visualgeom"/>
                                    <body name="L_ring_tip" pos="-0.002 -0.04 -0.004" />
                                  </body>
                                </body>
                                <body name="L_pinky_proximal" pos="-0.025488 0.00028533 -0.13571" quat="0.525481 0.473147 0.525485 0.473147">
                                  <inertial pos="0.0012971 -0.011934 -0.0059999" quat="0.489677 0.510114 -0.489692 0.510099" mass="0.0042405" diaginertia="6.9402e-07 6.62904e-07 2.10916e-07" />
                                  <geom type="mesh" contype="0" conaffinity="0" group="1" density="0" rgba="0.75294 0.75294 0.75294 1" mesh="L_pinky_proximal" />
                                  <geom type="mesh" rgba="0.75294 0.75294 0.75294 1" mesh="L_pinky_proximal" class="visualgeom"/>
                                  <body name="L_pinky_intermediate" pos="-0.0024229 -0.032041 -0.001">
                                    <inertial pos="0.0024788 -0.016208 -0.0050001" quat="0.526797 0.471683 -0.526793 0.471687" mass="0.0036036" diaginertia="4.4881e-07 4.43809e-07 6.5736e-08" />
                                    <geom type="mesh" contype="0" conaffinity="0" group="1" density="0" rgba="0.75294 0.75294 0.75294 1" mesh="L_pinky_intermediate" />
                                    <geom type="mesh" rgba="0.75294 0.75294 0.75294 1" mesh="L_pinky_intermediate" class="visualgeom"/>
                                    <body name="L_pinky_tip" pos="-0.002 -0.032 -0.004" />
                                  </body>
                                </body>
                              </body>
                            </body>
                          </body>
                        </body>
                      </body>
                    </body>
                  </body>
                </body>
              </body>
              <body name="right_upper_arm_pitch_link" pos="0 -0.10111 0.047149" quat="0.976296 -0.216438 0 0">
                <inertial pos="0.00515735 -0.0587916 0.000122944" quat="0.999675 -0.0254775 -0.000125407 -0.000494276" mass="0.777391" diaginertia="0.00054641 0.000340601 0.00031934" />
                <geom type="mesh" contype="0" conaffinity="0" group="1" density="0" rgba="0.75294 0.75294 0.75294 1" mesh="right_upper_arm_pitch_link" />
                <geom type="mesh" rgba="0.75294 0.75294 0.75294 1" mesh="right_upper_arm_pitch_link" class="visualgeom"/>
                <body name="right_upper_arm_roll_link" pos="0 -0.09515 0" quat="0.997189 0.0749297 0 0">
                  <inertial pos="0.026006 -0.023826 -0.027211" quat="0.906733 -0.298528 0.228699 0.190823" mass="0.084111" diaginertia="9.66585e-05 8.99068e-05 2.54689e-05" />
                  <geom type="mesh" contype="0" conaffinity="0" group="1" density="0" rgba="0.75294 0.75294 0.75294 1" mesh="right_upper_arm_roll_link" />
                  <geom type="mesh" rgba="0.75294 0.75294 0.75294 1" mesh="right_upper_arm_roll_link" class="visualgeom"/>
                  <body name="right_upper_arm_yaw_link" pos="0 -0.04 -0.07095">
                    <inertial pos="7.6e-05 -0.002032 -0.08519" quat="0.999725 -0.0150371 -4.36925e-05 -0.0179929" mass="0.55" diaginertia="0.00354301 0.00353897 0.000248224" />
                    <geom type="mesh" contype="0" conaffinity="0" group="1" density="0" rgba="0.75294 0.75294 0.75294 1" mesh="right_upper_arm_yaw_link" />
                    <geom type="mesh" rgba="0.75294 0.75294 0.75294 1" mesh="right_upper_arm_yaw_link" class="visualgeom"/>
<!--                    <geom name="right_upper_arm_yaw_link.STL" size="0.0362332 0.084942" pos="3.94854e-05 0.00089429 -0.07934" type="cylinder" rgba="0.752941 0.752941 0.752941 1" />-->
                    <body name="right_lower_arm_pitch_link" pos="0 0 -0.1751" quat="0.988771 0 -0.149438 0">>
                     <inertial pos="2.5454e-07 -0.019691 -0.021093" quat="0.675237 0.209883 -0.209892 0.675241" mass="0.055396" diaginertia="2.92255e-05 2.63267e-05 1.32931e-05" />
                      <geom type="mesh" contype="0" conaffinity="0" group="1" density="0" rgba="0.75294 0.75294 0.75294 1" mesh="right_lower_arm_pitch_link" />
                      <geom type="mesh" rgba="0.75294 0.75294 0.75294 1" mesh="right_lower_arm_pitch_link" class="visualgeom"/>
                      <body name="right_hand_yaw_link" pos="0 -5.033e-05 -0.05395">
                        <inertial pos="3.9e-05 -0.00212 -0.06117" quat="0.998577 -0.00525175 0.0038125 0.0529257" mass="0.73" diaginertia="0.00186612 0.00186214 0.00032084" />
                        <geom type="mesh" contype="0" conaffinity="0" group="1" density="0" rgba="0.75294 0.75294 0.75294 1" mesh="right_hand_yaw_link" />
                        <geom type="mesh" rgba="0.75294 0.75294 0.75294 1" mesh="right_hand_yaw_link" class="visualgeom"/>
<!--                        <geom name="right_hand_yaw_link.STL" size="0.0415719 0.0695937" pos="0.00108925 0.000641114 -0.0760429" type="cylinder" rgba="0.752941 0.752941 0.752941 1" />-->
                        <body name="right_hand_roll_link" pos="0 0 -0.18765">
                          <inertial pos="0 -0.00129 -0.0117" quat="0.404502 0.579981 0.404502 0.579981" mass="0.0295" diaginertia="1.01694e-05 8.75063e-06 5.38e-06" />
                          <geom type="mesh" contype="0" conaffinity="0" group="1" density="0" rgba="0.75294 0.75294 0.75294 1" mesh="right_hand_roll_link" />
                          <geom type="mesh" rgba="0.75294 0.75294 0.75294 1" mesh="right_hand_roll_link" class="visualgeom"/>
                          <body name="right_hand_pitch_link">
                            <inertial pos="0 -0.00129 -0.0117" quat="0.404502 0.579981 0.404502 0.579981" mass="0.0295" diaginertia="1.01694e-05 8.75063e-06 5.38e-06" />
                            <geom type="mesh" contype="0" conaffinity="0" group="1" density="0" rgba="0.75294 0.75294 0.75294 1" mesh="right_hand_pitch_link" />
                            <geom type="mesh" rgba="0.75294 0.75294 0.75294 1" mesh="right_hand_pitch_link" class="visualgeom"/>
                            <body name="right_end_effector_link">
                              <body name="R_hand_base_link" pos="0 0 -0.022">
                                <inertial pos="-0.0025264 -0.066047 0.0019598" quat="0.993005 -0.113528 -0.0210604 0.0246792" mass="0.14143" diaginertia="0.000122991 8.41186e-05 7.61951e-05" />
                                <geom type="mesh" contype="0" conaffinity="0" group="1" density="0" rgba="0.75294 0.75294 0.75294 1" mesh="R_hand_base_link" />
                                <geom type="mesh" rgba="0.75294 0.75294 0.75294 1" mesh="R_hand_base_link" class="visualgeom"/>
                                <body name="R_thumb_proximal_base" pos="0.02045 0.01696 -0.0691" quat="-3.67321e-06 0 1 0">
                                  <inertial pos="-0.0048064 0.0009382 -0.00757" quat="0.515015 0.680854 0.408023 0.323596" mass="0.0018869" diaginertia="8.66026e-08 6.8732e-08 4.94194e-08" />
                                  <geom type="mesh" contype="0" conaffinity="0" group="1" density="0" rgba="0.75294 0.75294 0.75294 1" mesh="R_thumb_proximal_base" />
                                  <geom type="mesh" rgba="0.75294 0.75294 0.75294 1" mesh="R_thumb_proximal_base" class="visualgeom"/>
                                  <body name="R_thumb_proximal" pos="-0.0088099 0.010892 -0.00925" quat="0.0996843 0.0996847 0.700046 0.700044">
                                    <inertial pos="0.021932 0.012785 -0.0080386" quat="-0.254474 0.660716 0.251893 0.659733" mass="0.0066075" diaginertia="2.78601e-06 2.43933e-06 8.64566e-07" />
                                    <geom type="mesh" contype="0" conaffinity="0" group="1" density="0" rgba="0.75294 0.75294 0.75294 1" mesh="R_thumb_proximal" />
                                    <geom type="mesh" rgba="0.75294 0.75294 0.75294 1" mesh="R_thumb_proximal" class="visualgeom"/>
                                    <body name="R_thumb_intermediate" pos="0.04407 0.034553 -0.0008">
                                      <inertial pos="0.0095544 -0.0016282 -0.0071997" quat="0.636718 0.307389 -0.636802 0.307548" mass="0.0037847" diaginertia="4.6531e-07 4.48089e-07 2.45661e-07" />
                                      <geom type="mesh" contype="0" conaffinity="0" group="1" density="0" rgba="0.75294 0.75294 0.75294 1" mesh="R_thumb_intermediate" />
                                      <geom type="mesh" rgba="0.75294 0.75294 0.75294 1" mesh="R_thumb_intermediate" class="visualgeom"/>
                                      <body name="R_thumb_distal" pos="0.020248 0.010156 -0.0012">
                                        <inertial pos="0.0092888 0.0049529 -0.0060033" quat="-0.266294 0.655967 0.262806 0.655537" mass="0.0033441" diaginertia="2.0026e-07 1.95247e-07 8.1593e-08" />
                                        <geom type="mesh" contype="0" conaffinity="0" group="1" density="0" rgba="0.75294 0.75294 0.75294 1" mesh="R_thumb_distal" />
                                        <geom type="mesh" rgba="0.75294 0.75294 0.75294 1" mesh="R_thumb_distal" class="visualgeom"/>
                                        <body name="R_thumb_tip" pos="0.015 0.013 -0.004" />
                                      </body>
                                    </body>
                                  </body>
                                </body>
                                <body name="R_index_proximal" pos="0.032268 0.00028533 -0.13653" quat="0.508647 -0.491199 0.491201 -0.508648">
                                  <inertial pos="0.0012259 0.011942 -0.0060001" quat="0.50867 0.49121 -0.508643 0.491172" mass="0.0042403" diaginertia="6.9398e-07 6.62871e-07 2.10909e-07" />
                                  <geom type="mesh" contype="0" conaffinity="0" group="1" density="0" rgba="0.75294 0.75294 0.75294 1" mesh="R_index_proximal" />
                                  <geom type="mesh" rgba="0.75294 0.75294 0.75294 1" mesh="R_index_proximal" class="visualgeom"/>
                                  <body name="R_index_intermediate" pos="-0.0026138 0.032026 -0.001">
                                    <inertial pos="0.0019697 0.019589 -0.005" quat="0.466773 0.531152 -0.466773 0.531153" mass="0.0045683" diaginertia="7.8179e-07 7.72465e-07 8.47212e-08" />
                                    <geom type="mesh" contype="0" conaffinity="0" group="1" density="0" rgba="0.75294 0.75294 0.75294 1" mesh="R_index_intermediate" />
                                    <geom type="mesh" rgba="0.75294 0.75294 0.75294 1" mesh="R_index_intermediate" class="visualgeom"/>
                                    <body name="R_index_tip" pos="-0.005 0.04 -0.004" />
                                  </body>
                                </body>
                                <body name="R_middle_proximal" pos="0.01295 0.00028533 -0.1371" quat="0.499998 -0.5 0.500002 -0.5">
                                  <inertial pos="0.001297 0.011934 -0.0060001" quat="0.510131 0.489693 -0.510105 0.489653" mass="0.0042403" diaginertia="6.9397e-07 6.62865e-07 2.10915e-07" />
                                  <geom type="mesh" contype="0" conaffinity="0" group="1" density="0" rgba="0.75294 0.75294 0.75294 1" mesh="R_middle_proximal" />
                                  <geom type="mesh" rgba="0.75294 0.75294 0.75294 1" mesh="R_middle_proximal" class="visualgeom"/>
                                  <body name="R_middle_intermediate" pos="-0.0024229 0.032041 -0.001">
                                    <inertial pos="0.001921 0.020796 -0.005" quat="0.466148 0.531627 -0.466229 0.531705" mass="0.0050396" diaginertia="9.8384e-07 9.73279e-07 9.14014e-08" />
                                     <geom type="mesh" contype="0" conaffinity="0" group="1" density="0" rgba="0.75294 0.75294 0.75294 1" mesh="R_middle_intermediate" />
                                     <geom type="mesh" rgba="0.75294 0.75294 0.75294 1" mesh="R_middle_intermediate" class="visualgeom"/>
                                    <body name="R_middle_tip" pos="-0.005 0.045 -0.004" />
                                  </body>
                                </body>
                                <body name="R_ring_proximal" pos="-0.0062872 0.00028533 -0.13691" quat="0.486728 -0.512927 0.512929 -0.48673">
                                  <inertial pos="0.001297 0.011934 -0.0060002" quat="0.510129 0.489691 -0.510107 0.489654" mass="0.0042403" diaginertia="6.9397e-07 6.62865e-07 2.10915e-07" />
                                  <geom type="mesh" contype="0" conaffinity="0" group="1" density="0" rgba="0.75294 0.75294 0.75294 1" mesh="R_ring_proximal" />
                                  <geom type="mesh" rgba="0.75294 0.75294 0.75294 1" mesh="R_ring_proximal" class="visualgeom"/>
                                  <body name="R_ring_intermediate" pos="-0.0024229 0.032041 -0.001">
                                    <inertial pos="0.0021753 0.019567 -0.005" quat="0.469554 0.528695 -0.469554 0.528695" mass="0.0045683" diaginertia="7.8177e-07 7.72448e-07 8.4722e-08" />
                                    <geom type="mesh" contype="0" conaffinity="0" group="1" density="0" rgba="0.75294 0.75294 0.75294 1" mesh="R_ring_intermediate" />
                                    <geom type="mesh" rgba="0.75294 0.75294 0.75294 1" mesh="R_ring_intermediate" class="visualgeom"/>
                                    <body name="R_ring_tip" pos="-0.002 0.04 -0.004" />
                                  </body>
                                </body>
                                <body name="R_pinky_proximal" pos="-0.025488 0.00028533 -0.13571" quat="0.47357 -0.525099 0.525101 -0.473572">
                                  <inertial pos="0.001297 0.011934 -0.0060001" quat="0.51013 0.489693 -0.510106 0.489653" mass="0.0042403" diaginertia="6.9397e-07 6.62865e-07 2.10915e-07" />
                                  <geom type="mesh" contype="0" conaffinity="0" group="1" density="0" rgba="0.75294 0.75294 0.75294 1" mesh="R_pinky_proximal" />
                                  <geom type="mesh" rgba="0.75294 0.75294 0.75294 1" mesh="R_pinky_proximal" class="visualgeom"/>
                                  <body name="R_pinky_intermediate" pos="-0.0024229 0.032041 -0.001">
                                    <inertial pos="0.0024748 0.016203 -0.0050031" quat="0.47398 0.528862 -0.469291 0.524799" mass="0.0035996" diaginertia="4.4867e-07 4.43723e-07 6.56538e-08" />
                                    <geom type="mesh" contype="0" conaffinity="0" group="1" density="0" rgba="0.75294 0.75294 0.75294 1" mesh="R_pinky_intermediate" />
                                    <geom type="mesh" rgba="0.75294 0.75294 0.75294 1" mesh="R_pinky_intermediate" class="visualgeom"/>
                                    <body name="R_pinky_tip" pos="-0.002 0.032 -0.004" />
                                  </body>
                                </body>
                              </body>
                            </body>
                          </body>
                        </body>
                      </body>
                    </body>
                  </body>
                </body>
              </body>
              <body name="head_yaw_link" pos="0 0 0.17339">
                <inertial pos="-0.0001367 -0.000134 0.05313" quat="0.698092 -0.00588508 -0.00754886 0.715944" mass="0.45" diaginertia="0.000769225 0.000735883 0.000168892" />
                <geom type="mesh" contype="0" conaffinity="0" group="1" density="0" rgba="0.75294 0.75294 0.75294 1" mesh="head_yaw_link" />
                <geom type="mesh" rgba="0.75294 0.75294 0.75294 1" mesh="head_yaw_link" class="visualgeom"/>
                <body name="head_roll_link" pos="0 -0.00105 0.14195">
                  <inertial pos="-3e-05 0.01418 -0.00267" quat="0.351424 0.150117 -0.834883 0.396152" mass="0.1267" diaginertia="2.08875e-05 2.00047e-05 1.56779e-05" />
                  <geom type="mesh" contype="0" conaffinity="0" group="1" density="0" rgba="0.75294 0.75294 0.75294 1" mesh="head_roll_link" />
                  <geom type="mesh" rgba="0.75294 0.75294 0.75294 1" mesh="head_roll_link" class="visualgeom"/>
                  <body name="head_pitch_link">
                    <inertial pos="0.02654 0.002225 -0.01063" quat="0.0180722 0.851262 -0.0107447 0.52432" mass="0.45" diaginertia="0.00165781 0.00141479 0.000966401" />
                    <geom type="mesh" contype="0" conaffinity="0" group="1" density="0" rgba="0.75294 0.75294 0.75294 1" mesh="head_pitch_link" />
                    <geom type="mesh" rgba="0.75294 0.75294 0.75294 1" mesh="head_pitch_link" class="visualgeom"/>
<!--                    <geom name="head_pitch_link.STL" size="0.108687" pos="0.0182811 0 -0.013362" rgba="0.752941 0.752941 0.752941 1" />-->
                  </body>
                </body>
              </body>
            </body>
          </body>
        </body>
      </body>
      <body name="IMU_link" pos="-0.064772 0 -0.0596">
        <inertial pos="-0.0003275 0 -0.005737" quat="0 0.687028 0 0.726631" mass="0.05" diaginertia="1.44301e-05 1.199e-05 1.12099e-05" />
        <geom name="IMU_link.STL" type="mesh" rgba="0.752941 0.752941 0.752941 1" mesh="IMU_link" />
      </body>
    </body>
  </worldbody>

  <actuator>
        <!-- left leg -->
        <motor class="GR1T1_inspire_hand_simple_coll" name="left_thigh_roll_link" joint="left_hip_roll_joint" ctrlrange="-80 80"/>
        <motor class="GR1T1_inspire_hand_simple_coll" name="left_thigh_yaw_link" joint="left_hip_yaw_joint" ctrlrange="-60 60"/>
        <motor class="GR1T1_inspire_hand_simple_coll" name="left_thigh_pitch_link" joint="left_hip_pitch_joint" ctrlrange="-160 160"/>
        <motor class="GR1T1_inspire_hand_simple_coll" name="left_shank_pitch_link" joint="left_knee_pitch_joint" ctrlrange="-160 160"/>
        <motor class="GR1T1_inspire_hand_simple_coll" name="left_foot_pitch_link" joint="left_ankle_pitch_joint" ctrlrange="-16 16"/>
	    <motor class="GR1T1_inspire_hand_simple_coll" name="left_foot_roll_link" joint="left_ankle_roll_joint" ctrlrange="-16 16"/>

        <!-- right leg -->
        <motor class="GR1T1_inspire_hand_simple_coll" name="right_thigh_roll_link" joint="right_hip_roll_joint" ctrlrange="-80 80"/>
        <motor class="GR1T1_inspire_hand_simple_coll" name="right_thigh_yaw_link" joint="right_hip_yaw_joint" ctrlrange="-60 60"/>
        <motor class="GR1T1_inspire_hand_simple_coll" name="right_thigh_pitch_link" joint="right_hip_pitch_joint" ctrlrange="-160 160"/>
        <motor class="GR1T1_inspire_hand_simple_coll" name="right_shank_pitch_link" joint="right_knee_pitch_joint" ctrlrange="-160 160"/>
        <motor class="GR1T1_inspire_hand_simple_coll" name="right_foot_pitch_link" joint="right_ankle_pitch_joint" ctrlrange="-16 16"/>
	    <motor class="GR1T1_inspire_hand_simple_coll" name="right_foot_roll_link" joint="right_ankle_roll_joint" ctrlrange="-16 16"/>

    </actuator>
        <sensor>
           <actuatorpos name='left_leg_roll_joint_p'  actuator='left_thigh_roll_link' user='13'/>
           <actuatorpos name='left_leg_yaw_joint_p'  actuator='left_thigh_yaw_link' user='13'/>
           <actuatorpos name='left_leg_pitch_joint_p'  actuator='left_thigh_pitch_link' user='13'/>
           <actuatorpos name='left_knee_joint_p'  actuator='left_shank_pitch_link' user='13'/>
           <actuatorpos name='left_ankle_pitch_joint_p'  actuator='left_foot_pitch_link' user='13'/>
           <actuatorpos name='left_ankle_roll_joint_p'  actuator='left_foot_roll_link' user='13'/>
           <actuatorpos name='right_leg_roll_joint_p'  actuator='right_thigh_roll_link' user='13'/>
           <actuatorpos name='right_leg_yaw_joint_p'  actuator='right_thigh_yaw_link' user='13'/>
           <actuatorpos name='right_leg_pitch_joint_p'  actuator='right_thigh_pitch_link' user='13'/>
           <actuatorpos name='right_knee_joint_p'  actuator='right_shank_pitch_link' user='13'/>
           <actuatorpos name='right_ankle_pitch_joint_p'  actuator='right_foot_pitch_link' user='13'/>
           <actuatorpos name='right_ankle_roll_joint_p'  actuator='right_foot_roll_link' user='13'/>


           <actuatorvel name='left_leg_roll_joint_v'  actuator='left_thigh_roll_link' user='13'/>
           <actuatorvel name='left_leg_yaw_joint_v'  actuator='left_thigh_yaw_link' user='13'/>
           <actuatorvel name='left_leg_pitch_joint_v'  actuator='left_thigh_pitch_link' user='13'/>
           <actuatorvel name='left_knee_joint_v'  actuator='left_shank_pitch_link' user='13'/>
           <actuatorvel name='left_ankle_pitch_joint_v'  actuator='left_foot_pitch_link' user='13'/>
           <actuatorvel name='left_ankle_roll_joint_v'  actuator='left_foot_roll_link' user='13'/>
           <actuatorvel name='right_leg_roll_joint_v'  actuator='right_thigh_roll_link' user='13'/>
           <actuatorvel name='right_leg_yaw_joint_v'  actuator='right_thigh_yaw_link' user='13'/>
           <actuatorvel name='right_leg_pitch_joint_v'  actuator='right_thigh_pitch_link' user='13'/>
           <actuatorvel name='right_knee_joint_v'  actuator='right_shank_pitch_link' user='13'/>
           <actuatorvel name='right_ankle_pitch_joint_v'  actuator='right_foot_pitch_link' user='13'/>
           <actuatorvel name='right_ankle_roll_joint_v'  actuator='right_foot_roll_link' user='13'/>

 
           <actuatorfrc name='left_leg_roll_joint_f'  actuator='left_thigh_roll_link' user='13' noise='1e-3'/>
           <actuatorfrc name='left_leg_yaw_joint_f'  actuator='left_thigh_yaw_link' user='13' noise='1e-3'/>
           <actuatorfrc name='left_leg_pitch_joint_f'  actuator='left_thigh_pitch_link' user='13' noise='1e-3'/>
           <actuatorfrc name='left_knee_joint_f'  actuator='left_shank_pitch_link' user='13' noise='1e-3'/>
           <actuatorfrc name='left_ankle_pitch_joint_f'  actuator='left_foot_pitch_link' user='13' noise='1e-3'/>
           <actuatorfrc name='left_ankle_roll_joint_f'  actuator='left_foot_roll_link' user='13' noise='1e-3'/>
           <actuatorfrc name='right_leg_roll_joint_f'  actuator='right_thigh_roll_link' user='13' noise='1e-3'/>
           <actuatorfrc name='right_leg_yaw_joint_f'  actuator='right_thigh_yaw_link' user='13' noise='1e-3'/>
           <actuatorfrc name='right_leg_pitch_joint_f'  actuator='right_thigh_pitch_link' user='13' noise='1e-3'/>
           <actuatorfrc name='right_knee_joint_f'  actuator='right_shank_pitch_link' user='13' noise='1e-3'/>
           <actuatorfrc name='right_ankle_pitch_joint_f'  actuator='right_foot_pitch_link' user='13' noise='1e-3'/>
           <actuatorfrc name='right_ankle_roll_joint_f'  actuator='right_foot_roll_link' user='13' noise='1e-3'/>

         
       <framequat     name='orientation' objtype='site' noise='0.001' objname='imu'/>
	   <framepos     name='position' objtype='site' noise='0.001' objname='imu'/>
	   <gyro          name='angular-velocity'    site='imu' noise='0.005' cutoff='34.9'/>
	   <velocimeter   name='linear-velocity'     site='imu' noise='0.001' cutoff='30'/>
	   <accelerometer name='linear-acceleration' site='imu' noise='0.005' cutoff='157'/>
	   <magnetometer  name='magnetometer'        site='imu'/>
        </sensor>

</mujoco>
